Workbook

Sheet Кратко Смета
A1: № | B1: Наименование работ | C1: Смета | E1: Стоимсоть работ (Ресурсная смета) | G1: КП 1 | I1: КП 2 | K1: КП 3 | M1: Работы по факту | O1: Примечание
A2: 1 | B2: Демонтаж перегородок (ЛИТЕР Е) | C2: Статус | D2: "-" | E2: Статус | F2: "-" | G2: Статус | H2: "-" | I2: Статус | J2: "-" | K2: Статус | L2: "-" | M2: Статус | N2: Выполнены | O2: Готовится КС 1
C3: Дата | E3: Дата | G3: Дата | I3: Дата | K3: Дата
C4: Статус | D4: "-" | E4: Статус | F4: "-" | G4: Статус | H4: "-" | I4: Статус | J4: "-" | K4: Статус | L4: "-"
C5: Дата | E5: Дата | G5: Дата | I5: Дата | K5: Дата
C6: Статус | D6: "-" | E6: Статус | F6: "-" | G6: Статус | H6: "-" | I6: Статус | J6: "-" | K6: Статус | L6: "-"
C7: Дата | E7: Дата | G7: Дата | I7: Дата | K7: Дата | M7: Дата
C8: Статус | D8: "-" | E8: Статус | F8: "-" | G8: Статус | H8: "-" | I8: Статус | J8: Пусто | K8: Статус | L8: "-"
C9: Дата | E9: Дата | G9: Дата | I9: Дата | K9: Дата
C10: Сметная стоимость | D10: =Смета_лит.Е!#REF!+Смета_лит.Е!#REF!+(Смета_лит.Е!#REF!/2) -> #REF! | E10: Сметная стоимость | F10: =D10*35% -> #REF! | G10: Компания | H10: РЕБУС | I10: Компания | J10: СПЕЦ-М | K10: Компания | L10: ООО "Сибеон"
G11: Стоимость | H11: 63816 | I11: Стоимость | J11: 81825.6 | K11: Стоимость | L11: 79382.4
A13: 2 | B13: Демонтаж полов (ЛИТЕР Е) | C13: Статус | D13: "-" | E13: Статус | F13: "-" | G13: Статус | H13: Отправлен | I13: Статус | J13: Отправлен | K13: Статус | L13: Отправлен | M13: Статус | N13: Выполнены | O13: Отправлены
C14: Дата | E14: Дата | G14: Дата | H14: 44972 | I14: Дата | J14: 44972 | K14: Дата | L14: 44972
C15: Статус | D15: "-" | E15: Статус | F15: "-" | G15: Статус | H15: Подготовлен | I15: Статус | J15: Подготовлен | K15: Статус | L15: "-"
C16: Дата | E16: Дата | G16: Дата | H16: 44973 | I16: Дата | J16: 44984 | K16: Дата
C17: Статус | D17: "-" | E17: Статус | F17: "-" | G17: Статус | H17: "-" | I17: Статус | J17: Подготовлен | K17: Статус | L17: "-"
C18: Дата | E18: Дата | G18: Дата | I18: Дата | K18: Дата | M18: Дата
C19: Статус | D19: "-" | E19: Статус | F19: "-" | G19: Статус | H19: "-" | I19: Статус | J19: "-" | K19: Статус | L19: "-"
C20: Дата | E20: Дата | G20: Дата | I20: Дата | K20: Дата
C21: Сметная стоимость | D21: =Смета_лит.Е!#REF!+Смета_лит.Е!#REF!+Смета_лит.Е!#REF!+Смета_лит.Е!#REF!+(Смета_лит.Е!#REF!/2) -> #REF! | E21: Сметная стоимость | F21: =D21*35% -> #REF! | G21: Компания | H21: РЕБУС | I21: Компания | J21: ИП Чернат | K21: Компания | L21: СПЕЦ-М
G22: Стоимость | H22: 80221 | I22: Стоимость | J22: 73965 | K22: Стоимость | L22: 90318
A24: 3 | B24: Демонтаж окон и дверей (ЛИТЕР Е) + монтаж уголка | C24: Статус | D24: "-" | E24: Статус | F24: "-" | G24: Статус | H24: "-" | I24: Статус | J24: "-" | K24: Статус | L24: "-" | M24: Статус | N24: Выполнены
C25: Дата | E25: Дата | G25: Дата | I25: Дата | K25: Дата
C26: Статус | D26: "-" | E26: Статус | F26: "-" | G26: Статус | H26: "-" | I26: Статус | J26: "-" | K26: Статус | L26: "-"
C27: Дата | E27: Дата | G27: Дата | I27: Дата | K27: Дата
C28: Статус | D28: "-" | E28: Статус | F28: "-" | G28: Статус | H28: "-" | I28: Статус | J28: "-" | K28: Статус | L28: "-"
C29: Дата | E29: Дата | G29: Дата | I29: Дата | K29: Дата | M29: Дата
C30: Статус | D30: "-" | E30: Статус | F30: "-" | G30: Статус | H30: "-" | I30: Статус | J30: Пусто | K30: Статус | L30: "-"
C31: Дата | E31: Дата | G31: Дата | I31: Дата | K31: Дата
C32: Сметная стоимость | D32: 130000 | E32: Сметная стоимость | F32: =D32*35% -> 45500 | G32: Компания | H32: РЕБУС | I32: Компания | J32: СПЕЦ-М | K32: Компания | L32: Сибеон
G33: Стоимость | H33: 66000 | I33: Стоимость | J33: 75120 | K33: Стоимость | L33: 94560
A35: 4 | B35: Прокладка греющего кабеля СОК | C35: Статус | D35: "-" | E35: Статус | F35: "-" | G35: Статус | H35: "-" | I35: Статус | J35: "-" | K35: Статус | L35: "-" | M35: Статус | N35: Выполнены
C36: Дата | E36: Дата | G36: Дата | I36: Дата | K36: Дата
C37: Статус | D37: "-" | E37: Статус | F37: "-" | G37: Статус | H37: "-" | I37: Статус | J37: "-" | K37: Статус | L37: "-"
C38: Дата | E38: Дата | G38: Дата | I38: Дата | K38: Дата
C39: Статус | D39: "-" | E39: Статус | F39: "-" | G39: Статус | H39: "-" | I39: Статус | J39: "-" | K39: Статус | L39: "-"
C40: Дата | E40: Дата | G40: Дата | I40: Дата | K40: Дата | M40: Дата
C41: Статус | D41: "-" | E41: Статус | F41: "-" | G41: Статус | H41: "-" | I41: Статус | J41: Пусто | K41: Статус | L41: "-"
C42: Дата | E42: Дата | G42: Дата | I42: Дата | K42: Дата
C43: Сметная стоимость | E43: Сметная стоимость | F43: =D43*35% -> 0 | G43: Компания | H43: РЕБУС | I43: Компания | J43: СПЕЦ-М | K43: Компания | L43: ИП Назаров
...

Sheet Смета_лит.Е
B1: Исх. № 39/1 от «13» декабря 2022г.
B2: ЛОКАЛЬНАЯ СМЕТА
A3: на выполнение СМР в здании Литер «Е»
A4: Адрес объекта: г. Санкт-Петербург, ш. Приморское, д. 696, ДОК «Буревестник», здание лит "Е".
A5: № п/п | B5: Наименование работ | C5: Ед. изм. | D5: Кол-во | E5: ст-ть за ед. работ | F5: ст-ть работ | G5: ст-ть за ед. работ | H5: ст-ть работ
E6: Наши цены | G6: Компания 1
A7: 12 | B7: ПОЛЫ ВЫРАВНИВАНИЕ
A8: 12.1 | B8: Подливка полов самовыравнивающимся составом | C8: м2 | D8: 120 | E8: 370 | F8: =D8*E8 -> 44400 | H8: =G8*D8 -> 0
A9: 12.2 | B9: Устройство обмазочной гидроизоляции с заводом на стену с предварительной огрунтовкой (2 слоя) | C9: м2 | D9: 18.72 | E9: 350 | F9: =D9*E9 -> 6552 | H9: =G9*D9 -> 0
A10: 12.3 | B10: Монтаж упрочняющей ленты (стык пол-стена) | C10: м.п | D10: 60.88 | E10: 150 | F10: =D10*E10 -> 9132 | H10: =G10*D10 -> 0
A11: 12.4 | B11: Грунтование поверхности пола | C11: м2 | D11: 195.84 | E11: 250 | F11: =D11*E11 -> 48960 | H11: =G11*D11 -> 0
A12: 14 | B12: ЧЕРНОВЫЕ ЭЛЕКТРО-МОНТАЖНЫЕ РАБОТЫ | H12: =G12*D12 -> 0
A13: 14.1 | B13: Прокладка силовых кабелей в гофре | C13: м.п | D13: 1770 | E13: 120 | F13: =D13*E13 -> 212400 | H13: =G13*D13 -> 0
A14: 14.2 | B14: Установка коробок (монтажные, разветвительные) с расключением кабелей | C14: шт | D14: 40 | E14: 750 | F14: =D14*E14 -> 30000 | H14: =G14*D14 -> 0
A15: 14.3 | B15: Монтаж электрощита | C15: шт | D15: 8 | E15: 1800 | F15: =D15*E15 -> 14400 | H15: =G15*D15 -> 0
A16: 14.4 | B16: Монтаж автоматического выключателя 2-х полюсного | C16: шт | D16: 8 | E16: 350 | F16: =D16*E16 -> 2800 | H16: =G16*D16 -> 0
A17: 14.5 | B17: Монтаж УЗО | C17: шт | D17: 8 | E17: 600 | F17: =D17*E17 -> 4800 | H17: =G17*D17 -> 0
A18: 14.6 | B18: Монтаж автоматического выключателя однополюсного | C18: шт | D18: 48 | E18: 250 | F18: =D18*E18 -> 12000 | H18: =G18*D18 -> 0
A19: 14.7 | B19: Монтаж пожрозетников | C19: шт | D19: 64 | E19: 100 | F19: =D19*E19 -> 6400 | H19: =G19*D19 -> 0
A20: 15 | B20: ПРОКЛАДКА ВЕНТИЛЯЦИИ | H20: =G20*D20 -> 0
A21: 15.1 | B21: Монтаж прямоугольных воздуховодов | C21: м.п. | D21: 24 | E21: 400 | F21: =D21*E21 -> 9600 | H21: =G21*D21 -> 0
A22: 16 | B22: ОБШИВКА СТЕН ГКЛ | H22: =G22*D22 -> 0
A23: 16.1 | B23: Однослойная облицовка из ГКЛ на металлическом каркасе, закрепленном на базовой стене с утеплителем | C23: м2 | D23: 355.44 | E23: 580 | F23: =D23*E23 -> 206155.2 | H23: =G23*D23 -> 0
A24: 17 | B24: МОНТАЖ ПЕРЕГОРОДОК ГКЛ | H24: =G24*D24 -> 0
A25: 17.1 | B25: Перегородка с однослойными обшивками из ГКЛ на одинарном металлическом каркасе с шумоизоляцией | C25: м2 | D25: 205 | E25: 580 | F25: =D25*E25 -> 118900 | H25: =G25*D25 -> 0
A26: 17.2 | B26: Монтаж закладных элементов из листовых материалов | C26: м2 | D26: 16 | E26: 150 | F26: =D26*E26 -> 2400 | H26: =G26*D26 -> 0
A27: 18 | B27: МОНТАЖ ПОТОЛКА ГКЛ | H27: =G27*D27 -> 0
A28: 18.1 | B28: Монтаж одноуровневого потолка ГКЛ | C28: м2 | D28: 154 | E28: 900 | F28: =D28*E28 -> 138600 | H28: =G28*D28 -> 0
A29: 19 | B29: ПОТОЛОК (Черновые работы) | H29: =G29*D29 -> 0
A30: 19.1 | B30: Заделка стыков и саморезов на ГКЛ | C30: м2 | D30: 154 | E30: 90 | F30: =D30*E30 -> 13860 | H30: =G30*D30 -> 0
A31: 19.2 | B31: Шпатлёвка потолка в 2 слоя с ошкуриванием (под окраску) | C31: м2 | D31: 154 | E31: 550 | F31: =D31*E31 -> 84700 | H31: =G31*D31 -> 0
A32: 20 | B32: МОНТАЖ ПОДОКОННИКОВ И ОТКОСОВ | H32: =G32*D32 -> 0
A33: 20.1 | B33: Монтаж подоконников и откосов | C33: к-кс | D33: 1 | E33: 40000 | F33: =D33*E33 -> 40000 | H33: =G33*D33 -> 0
A34: 21 | B34: ОТДЕЛКА ВХОДНЫХ ДВЕРЕЙ | H34: =G34*D34 -> 0
A35: 21.1 | B35: Отделка входных дверей | C35: к-кс | D35: 1 | E35: 20000 | F35: =D35*E35 -> 20000 | H35: =G35*D35 -> 0
A36: 22 | B36: СТЕНЫ (Черновые работы) | H36: =G36*D36 -> 0
A37: 22.1 | B37: Подготовка стен из ГКЛ к шпатлёвке (грунтование, проклейка стыков с укрытием, укрытие саморезов, шлифовка) | C37: м2 | D37: 532 | E37: 150 | F37: =D37*E37 -> 79800 | H37: =G37*D37 -> 0
A38: 22.2 | B38: Шпатлевание стен ГКЛ (подготовка к оклейке обоями) | C38: м2 | D38: =D37 -> 532 | E38: 350 | F38: =D38*E38 -> 186200 | H38: =G38*D38 -> 0
A39: 22.3 | B39: Шлифовка стен (под обои) | C39: м2 | D39: 532 | E39: 250 | F39: =D39*E39 -> 133000 | H39: =G39*D39 -> 0
A40: 23 | B40: МОНТАЖ СИСТЕМЫ ОТОПЛЕНИЯ | H40: =G40*D40 -> 0
...

Sheet Расчеты
A1: № | B1: Наименование работ | C1: Стоимость материалов (план) | D1: Стоимость материалов (факт) | E1: Стоимость работ (план) | F1: Стоимость работ (факт)
A2: 1 | B2: Демонтажные работы | C2: =SUM(Смета_лит.Е!#REF!) -> #REF! | D2: =C2*90% -> #REF! | E2: =SUM(Смета_лит.Е!#REF!) -> #REF! | F2: =E2*57% -> #REF!
A3: 2 | B3: Додемонтаж | C3: =SUM(Смета_лит.Е!#REF!) -> #REF! | D3: =C3*90% -> #REF! | E3: =SUM(Смета_лит.Е!#REF!) -> #REF! | F3: =E3*65% -> #REF!
A4: 3 | B4: Выямка грунта для полов | C4: =SUM(Смета_лит.Е!#REF!) -> #REF! | D4: =C4*90% -> #REF! | E4: =SUM(Смета_лит.Е!#REF!) -> #REF! | F4: =E4*65% -> #REF!
A5: 4 | B5: Кладочные работы (закладка окон)3100 кирипича 6 м3 с оставлением отверстий под вентиляцию | C5: =SUM(Смета_лит.Е!#REF!) -> #REF! | D5: =C5*90% -> #REF! | E5: =SUM(Смета_лит.Е!#REF!) -> #REF! | F5: =E5*65% -> #REF!
A6: 5 | B6: Монтаж окон с отливами (без подоконников и откосов) | C6: =SUM(Смета_лит.Е!#REF!) -> #REF! | D6: =C6*90% -> #REF! | E6: =SUM(Смета_лит.Е!#REF!) -> #REF! | F6: =E6*65% -> #REF!
A7: 6 | B7: Монтаж входных дверей (без отделки) | C7: =SUM(Смета_лит.Е!#REF!) -> #REF! | D7: =C7*90% -> #REF! | E7: =SUM(Смета_лит.Е!#REF!) -> #REF! | F7: =E7*65% -> #REF!
A8: 7 | B8: Устройство временного освещения и отопления | C8: =SUM(Смета_лит.Е!#REF!) -> #REF! | D8: =C8*90% -> #REF! | E8: =SUM(Смета_лит.Е!#REF!) -> #REF! | F8: =E8*65% -> #REF!
A9: 8 | B9: Монтаж водоотведения | C9: =SUM(Смета_лит.Е!#REF!) -> #REF! | D9: =C9*90% -> #REF! | E9: =SUM(Смета_лит.Е!#REF!) -> #REF! | F9: =E9*65% -> #REF!
A10: 9 | B10: Подвод горячего водоснабжения и системы отопления | D10: =C10*90% -> 0 | E10: =SUM(Смета_лит.Е!#REF!) -> #REF! | F10: =E10*65% -> #REF!
A11: 10 | B11: Черновой монтаж ГВС и ХВС | C11: =SUM(Смета_лит.Е!#REF!) -> #REF! | D11: =C11*90% -> #REF! | E11: =SUM(Смета_лит.Е!#REF!) -> #REF! | F11: =E11*65% -> #REF!
A12: 11 | B12: Полы (пирог по грунту) | C12: =SUM(Смета_лит.Е!#REF!) -> #REF! | D12: =C12*90% -> #REF! | E12: =SUM(Смета_лит.Е!#REF!) -> #REF! | F12: =E12*65% -> #REF!
A13: 12 | B13: Полы финальная стяжка | C13: =SUM(Смета_лит.Е!#REF!) -> #REF! | D13: =C13*90% -> #REF! | E13: =SUM(Смета_лит.Е!F8:F11) -> 109044 | F13: =E13*65% -> 70878.6
A14: 13 | B14: Разметка помщений | D14: =C14*90% -> 0 | F14: =E14*65% -> 0
A15: 14 | B15: Черновые электромонтажные работы (+Слаботочка выполняется, но считается отдельно) | C15: =SUM(Смета_лит.Е!#REF!) -> #REF! | D15: =C15*90% -> #REF! | E15: =SUM(Смета_лит.Е!F13:F19) -> 282800 | F15: =E15*65% -> 183820
A16: 15 | B16: Прокладка вентиляции | C16: =SUM(Смета_лит.Е!#REF!) -> #REF! | D16: =C16*90% -> #REF! | E16: =SUM(Смета_лит.Е!F21:F21) -> 9600 | F16: =E16*65% -> 6240
A17: 16 | B17: Обшивка стен ГКЛ | C17: =SUM(Смета_лит.Е!#REF!) -> #REF! | D17: =C17*90% -> #REF! | E17: =SUM(Смета_лит.Е!F23:F23) -> 206155.2 | F17: =E17*65% -> 134000.88
B18: Монтаж электрощита и подключение временного освещения | C18: Учтено выше. Это для порядка работ | F18: =E18*65% -> 0
A19: 17 | B19: Монтаж перегородок ГКЛ | C19: =SUM(Смета_лит.Е!#REF!) -> #REF! | D19: =C19*90% -> #REF! | E19: =SUM(Смета_лит.Е!F25:F26) -> 121300 | F19: =E19*65% -> 78845
A20: 18 | B20: Монтаж потолка ГКЛ | C20: =SUM(Смета_лит.Е!#REF!) -> #REF! | D20: =C20*90% -> #REF! | E20: =SUM(Смета_лит.Е!F28:F28) -> 138600 | F20: =E20*65% -> 90090
A21: 19 | B21: Отделка потолка черновая | C21: =SUM(Смета_лит.Е!#REF!) -> #REF! | D21: =C21*90% -> #REF! | E21: =SUM(Смета_лит.Е!F30:F31) -> 98560 | F21: =E21*65% -> 64064
A22: 20 | B22: Монтаж подоконников и откосов | C22: учтены выше | E22: =SUM(Смета_лит.Е!F33) -> 40000 | F22: =E22*65% -> 26000
A23: 21 | B23: Отделка входных дверей | D23: =C23*90% -> 0 | E23: =SUM(Смета_лит.Е!F35) -> 20000 | F23: =E23*65% -> 13000
A24: 22 | B24: Отделка стен черновая | C24: =SUM(Смета_лит.Е!#REF!) -> #REF! | D24: =C24*90% -> #REF! | E24: =SUM(Смета_лит.Е!F37:F39) -> 399000 | F24: =E24*65% -> 259350
A25: 23 | B25: Монтаж системы отопления | C25: =SUM(Смета_лит.Е!#REF!) -> #REF! | D25: =C25*90% -> #REF! | E25: =SUM(Смета_лит.Е!F41:F42) -> 160000 | F25: =E25*65% -> 104000
A26: 24 | B26: Укладка плитки на стены | C26: =SUM(Смета_лит.Е!#REF!) -> #REF! | D26: =C26*90% -> #REF! | E26: =SUM(Смета_лит.Е!F44:F44) -> 204375 | F26: =E26*65% -> 132843.75
A27: 25 | B27: Укладка плитки на пол | C27: =SUM(Смета_лит.Е!#REF!) -> #REF! | D27: =C27*90% -> #REF! | E27: =SUM(Смета_лит.Е!F46:F47) -> 128800 | F27: =E27*65% -> 83720
A28: 26 | B28: Монтаж реечного потолка ванна | C28: =SUM(Смета_лит.Е!#REF!) -> #REF! | D28: =C28*90% -> #REF! | E28: =SUM(Смета_лит.Е!F49:F49) -> 16066 | F28: =E28*65% -> 10442.9
A29: 27 | B29: Чистовая отделка потолка | C29: =SUM(Смета_лит.Е!#REF!) -> #REF! | D29: =C29*90% -> #REF! | E29: =SUM(Смета_лит.Е!F51:F52) -> 80300 | F29: =E29*65% -> 52195
A30: 28 | B30: Чистовая отделка стен | C30: =SUM(Смета_лит.Е!#REF!) -> #REF! | D30: =C30*90% -> #REF! | E30: =SUM(Смета_лит.Е!F54:F56) -> 273000 | F30: =E30*65% -> 177450
A31: 29 | B31: Укладка ламината | C31: =SUM(Смета_лит.Е!#REF!) -> #REF! | D31: =C31*90% -> #REF! | E31: =SUM(Смета_лит.Е!F58:F58) -> 61200 | F31: =E31*65% -> 39780
A32: 30 | B32: Монтаж межкомнатных дверей | C32: =SUM(Смета_лит.Е!#REF!) -> #REF! | D32: =C32*90% -> #REF! | E32: =SUM(Смета_лит.Е!F60:F60) -> 92800 | F32: =E32*65% -> 60320
A33: 31 | B33: Установка плинтусов | C33: =SUM(Смета_лит.Е!#REF!) -> #REF! | D33: =C33*90% -> #REF! | E33: =SUM(Смета_лит.Е!F62:F62) -> 54720 | F33: =E33*65% -> 35568
A34: 32 | B34: Чистовые электромонтажные работы | C34: =SUM(Смета_лит.Е!#REF!) -> #REF! | D34: =C34*90% -> #REF! | E34: =SUM(Смета_лит.Е!F64:F65) -> 61120 | F34: =E34*65% -> 39728
A35: 33 | B35: Установка сантехники | C35: =SUM(Смета_лит.Е!#REF!) -> #REF! | D35: =C35*90% -> #REF! | E35: =SUM(Смета_лит.Е!F67:F73) -> 109320 | F35: =E35*65% -> 71058
B38: Итого: | C38: =SUM(C2:C37) -> #REF! | D38: =SUM(D2:D35) -> #REF! | E38: =SUM(E2:E37) -> #REF! | F38: =SUM(F2:F37) -> #REF!
B39: Итого: | C39: План: | D39: =C38+E38 -> #REF! | E39: Факт: | F39: =D38+F38 -> #REF! | G39: Разница: | H39: =D39-F39 -> #REF!

Sheet Доп.
A1: Статус | B1: Статус | C1: Статус
A2: "-" | B2: "-" | C2: "-"
A3: Подготовлен | B3: Подготовлен | C3: Не выполнены
A4: Отправлен | B4: Отправлен | C4: Выполнены
A5: Редакция | B5: Ожидание
A6: На подписи | B6: На подписи
A7: Подписан | B7: Подписан
B8: Ответ получен
B9: Редакция

Sheet Лист1
A1: № п/п | B1: Наименование работ | C1: Ед. изм. | D1: Кол-во | E1: ст-ть за ед. работ | F1: ст-ть работ | G1: Ресурсная стоимость | H1: Количество смен | I1: Количество сотрудников | J1: Количество смен с учетом количества сотрудников | K1: Желаемое количество смен | L1: Фактическое количество смен
A2: 1 | B2: ДЕМОНТАЖНЫЕ РАБОТЫ
A3: 1.1 | B3: Демонтаж перегородок (доска + дранка) | C3: м2 | D3: 158.4 | E3: 450 | F3: =D3*E3 -> 71280 | G3: =F3*40% -> 28512 | H3: =G3/2500 -> 11.4048 | I3: 2 | J3: =H3/I3 -> 5.7024
A4: 1.2 | B4: Демонтаж полового настила (доска) | C4: м2 | D4: 189 | E4: 250 | F4: =D4*E4 -> 47250 | G4: =F4*40% -> 18900 | H4: =G4/2500 -> 7.56 | I4: 2 | J4: =H4/I4 -> 3.78
A5: 1.3 | B5: Демонтаж лаг (брус) | C5: м2 | D5: 189 | E5: 145 | F5: =D5*E5 -> 27405 | G5: =F5*40% -> 10962 | H5: =G5/2500 -> 4.3848 | I5: 2 | J5: =H5/I5 -> 2.1924
A6: 1.4 | B6: Демонтаж кафельной плитки с расчисткой основания от клеевого состава | C6: м2 | D6: 24 | E6: 250 | F6: =D6*E6 -> 6000 | G6: =F6*40% -> 2400 | H6: =G6/2500 -> 0.96 | I6: 2 | J6: =H6/I6 -> 0.48
A7: 1.5 | B7: Демонтаж радиаторов отопления и металлических труб | C7: м.п. | D7: 40 | E7: 210 | F7: =D7*E7 -> 8400 | G7: =F7*40% -> 3360 | H7: =G7/2500 -> 1.344 | I7: 2 | J7: =H7/I7 -> 0.672
A8: 1.6 | B8: Демонтаж кирпичной кладки | C8: м2 | D8: 18.7 | E8: 700 | F8: =D8*E8 -> 13090 | G8: =F8*40% -> 5236 | H8: =G8/2500 -> 2.0944 | I8: 2 | J8: =H8/I8 -> 1.0472
A9: 1.7 | B9: Снятие дверных коробок с полотнами (дерево + стекло) | C9: шт. | D9: 16 | E9: 1050 | F9: =D9*E9 -> 16800 | G9: =F9*40% -> 6720 | H9: =G9/2500 -> 2.688 | I9: 2 | J9: =H9/I9 -> 1.344
A10: 1.8 | B10: Демонтаж окон | C10: шт. | D10: 4 | E10: 900 | F10: =D10*E10 -> 3600 | G10: =F10*40% -> 1440 | H10: =G10/2500 -> 0.576 | I10: 2 | J10: =H10/I10 -> 0.288
A11: 1.9 | B11: Вынос строительного мусора (после демонтажа) | C11: тн | D11: 4.2 | E11: 2000 | F11: =D11*E11 -> 8400 | G11: =F11*40% -> 3360 | H11: =G11/2500 -> 1.344 | I11: 2 | J11: =H11/I11 -> 0.672
A12: 2 | B12: ДОДЕМОНТАЖ | G12: =F12*40% -> 0 | H12: =G12/2500 -> 0 | I12: 2 | J12: =H12/I12 -> 0
A13: 2.1 | B13: Додемонтажные работы (сбивка штукатурки с окон, зачистка дверных проемов и т.д.) | C13: к-кс | D13: 1 | E13: 15000 | F13: =D13*E13 -> 15000 | G13: =F13*40% -> 6000 | H13: =G13/2500 -> 2.4 | I13: 2 | J13: =H13/I13 -> 1.2
A14: 3 | B14: ВЫЯМКА ГРУНТА ДЛЯ ПОЛОВ | G14: =F14*40% -> 0 | H14: =G14/2500 -> 0 | I14: 2 | J14: =H14/I14 -> 0
A15: 3.1 | B15: Демонтаж стяжки (толщина не более 150мм) | C15: м2 | D15: 32 | E15: 500 | F15: =D15*E15 -> 16000 | G15: =F15*40% -> 6400 | H15: =G15/2500 -> 2.56 | I15: 2 | J15: =H15/I15 -> 1.28
A16: 3.2 | B16: Выямка грунта со строительным мусором (Н-300мм. S-197м2) | C16: м3 | D16: 60 | E16: 550 | F16: =D16*E16 -> 33000 | G16: =F16*40% -> 13200 | H16: =G16/2500 -> 5.28 | I16: 2 | J16: =H16/I16 -> 2.64
A17: 3.3 | B17: Демонтаж кирпичных опор деревянного пола | C17: м.п. | D17: 48 | E17: 700 | F17: =D17*E17 -> 33600 | G17: =F17*40% -> 13440 | H17: =G17/2500 -> 5.376 | I17: 2 | J17: =H17/I17 -> 2.688
A18: 4 | B18: КЛАДОЧНЫЕ РАБОТЫ | G18: =F18*40% -> 0 | H18: =G18/2500 -> 0 | I18: 2 | J18: =H18/I18 -> 0
A19: 4.1 | B19: Закладка дверных и оконных проемов | C19: м3 | D19: 6 | E19: 6800 | F19: =D19*E19 -> 40800 | G19: =F19*40% -> 16320 | H19: =G19/2500 -> 6.528 | I19: 2 | J19: =H19/I19 -> 3.264
A20: 4.2 | B20: Монтаж металлического уголка (над окнами и дверями)+сварочные работы | C20: шт | D20: 32 | E20: 1100 | F20: =D20*E20 -> 35200 | G20: =F20*40% -> 14080 | H20: =G20/2500 -> 5.632 | I20: 2 | J20: =H20/I20 -> 2.816
A21: 4.3 | B21: Устройство тепляка | C21: м2 | D21: 240 | E21: 100 | F21: =D21*E21 -> 24000 | G21: =F21*40% -> 9600 | H21: =G21/2500 -> 3.84 | I21: 2 | J21: =H21/I21 -> 1.92
A22: 5 | B22: ОКНА | G22: =F22*40% -> 0 | H22: =G22/2500 -> 0 | I22: 2 | J22: =H22/I22 -> 0
A23: 5.1 | B23: Монтаж окон без отделки | C23: шт | D23: 8 | E23: 3000 | F23: =D23*E23 -> 24000 | G23: =F23*40% -> 9600 | H23: =G23/2500 -> 3.84 | I23: 2 | J23: =H23/I23 -> 1.92
A24: 6 | B24: ВХОДНЫЕ ДВЕРИ | G24: =F24*40% -> 0 | H24: =G24/2500 -> 0 | I24: 2 | J24: =H24/I24 -> 0
A25: 6.1 | B25: Монтаж входных дверей (без отделки) | C25: шт | D25: 8 | E25: 2500 | F25: =D25*E25 -> 20000 | G25: =F25*40% -> 8000 | H25: =G25/2500 -> 3.2 | I25: 2 | J25: =H25/I25 -> 1.6
A26: 7 | B26: УСТРОЙСТВО ВРЕМЕННОГО ОСВЕЩЕНИЯ И ОТОПЛЕНИЯ | G26: =F26*40% -> 0 | H26: =G26/2500 -> 0 | I26: 2 | J26: =H26/I26 -> 0
A27: 7.1 | B27: Работы по устройству временного освещения и отопления | C27: к-кс | D27: 1 | E27: 7000 | F27: =D27*E27 -> 7000 | G27: =F27*40% -> 2800 | H27: =G27/2500 -> 1.12 | I27: 2 | J27: =H27/I27 -> 0.56
A28: 8 | B28: МОНТАЖ ВОДООТВЕДЕНИЯ | G28: =F28*40% -> 0 | H28: =G28/2500 -> 0 | I28: 2 | J28: =H28/I28 -> 0
A29: 8.1 | B29: Монтаж труб канализации | C29: точка | D29: 18 | E29: 1850 | F29: =D29*E29 -> 33300 | G29: =F29*40% -> 13320 | H29: =G29/2500 -> 5.328 | I29: 2 | J29: =H29/I29 -> 2.664
A30: 8.2 | B30: Пробивка отверстий в бетоне (более 200мм) | C30: шт | D30: 4 | E30: 2900 | F30: =D30*E30 -> 11600 | G30: =F30*40% -> 4640 | H30: =G30/2500 -> 1.856 | I30: 2 | J30: =H30/I30 -> 0.928
A31: 8.3 | B31: Можтаж металлических гильз | C31: шт | D31: 4 | E31: 1000 | F31: =D31*E31 -> 4000 | G31: =F31*40% -> 1600 | H31: =G31/2500 -> 0.64 | I31: 2 | J31: =H31/I31 -> 0.32
A32: 8.4 | B32: Замазка и запенивание гильз | C32: к-кс | D32: 4 | E32: 1000 | F32: =D32*E32 -> 4000 | G32: =F32*40% -> 1600 | H32: =G32/2500 -> 0.64 | I32: 2 | J32: =H32/I32 -> 0.32
A33: 9 | B33: ПОДВОД ГОРЯЧЕГО ВОДОСНАВЖЕНИЯ И ОТОПЛЕНИЯ | G33: =F33*40% -> 0 | H33: =G33/2500 -> 0 | I33: 2 | J33: =H33/I33 -> 0
A34: 9.1 | B34: Работы по подводу горячего водоснабжения и отопления | C34: к-кс | D34: 1 | E34: 30000 | F34: =D34*E34 -> 30000 | G34: =F34*40% -> 12000 | H34: =G34/2500 -> 4.8 | I34: 2 | J34: =H34/I34 -> 2.4
G35: =F35*40% -> 0 | H35: =G35/2500 -> 0 | I35: 2 | J35: =H35/I35 -> 0
A36: 10 | B36: ЧЕРНОВОЙ МОНТАЖ ГВС И ХВС | G36: =F36*40% -> 0 | H36: =G36/2500 -> 0 | I36: 2 | J36: =H36/I36 -> 0
A37: 10.1 | B37: Разводка труб ХВС, ГВС в земле | C37: м.п. | D37: 98 | E37: 210 | F37: =D37*E37 -> 20580 | G37: =F37*40% -> 8232 | H37: =G37/2500 -> 3.2928 | I37: 2 | J37: =H37/I37 -> 1.6464
A38: 10.2 | B38: Монтаж греющего кабеля | C38: м.п. | D38: 98 | E38: 180 | F38: =D38*E38 -> 17640 | G38: =F38*40% -> 7056 | H38: =G38/2500 -> 2.8224 | I38: 2 | J38: =H38/I38 -> 1.4112
A39: 10.3 | B39: Теплоизоляция труб | C39: м.п. | D39: 90 | E39: 100 | F39: =D39*E39 -> 9000 | G39: =F39*40% -> 3600 | H39: =G39/2500 -> 1.44 | I39: 2 | J39: =H39/I39 -> 0.72
A40: 10.4 | B40: Землянные работы | C40: к-кс | D40: 1 | E40: 5000 | F40: =D40*E40 -> 5000 | G40: =F40*40% -> 2000 | H40: =G40/2500 -> 0.8 | I40: 2 | J40: =H40/I40 -> 0.4
...
